Workbook

Sheet Worst Case
A1: WORST CASE | H1: OVERVIEW | S1: MERIT SHOP | AG1: AI COSTING
A2: SCENARIO INPUTS
A3: Total monthly users | B3: 120000
A4: Monthly Elite users | B4: 0.009 | E4: MAU tier distributions | F4: Free | G4: Elite | J4: MAU's | K4: =$B$3 -> 120000 | O4: Shop Prices | T4: Cost of features in Merits | Z4: Tokens per run - Input # | AD4: Tokens per run - Output # | AH4: Tokens per run - Cache Write # | AL4: Tokens per run - Cache Read #
A5: Annual Elite users | B5: 0.001 | E5: Monthly % | F5: =1-$B$4-$B$5 -> 0.99 | G5: =$B$4 -> 0.009 | O5: Count | P5: Price | Q5: Price per merit | T5: Features | U5: Free | V5: Elite | Z5: Features | AA5: Free | AB5: Elite | AD5: Features | AE5: Free | AF5: Elite | AH5: Features | AI5: Free | AJ5: Elite | AL5: Features | AM5: Free | AN5: Elite
E6: Annual % | F6: - | G6: =$B$5 -> 0.001 | J6: Monthly cost of plans | O6: ='Simple Inputs'!$E$27 -> 3 | P6: ='Simple Inputs'!$F$27 -> 1.99 | Q6: =P6/O6 -> 0.66333333 | T6: Resume Analysis | U6: 3 | V6: 3 | Z6: Resume Analysis | AA6: 5100 | AB6: 20000 | AD6: Resume Analysis | AE6: 4300 | AF6: 25000 | AH6: Resume Analysis | AI6: 0 | AJ6: 0 | AL6: Resume Analysis | AM6: 0 | AN6: 0
A7: MONTHLY RESULTS | E7: Monthly # | F7: =FLOOR(F5*$K$4, 1) -> 118800 | G7: =FLOOR(G5*$K$4, 1) -> 1080 | J7: Tier | K7: Free | L7: Elite | O7: ='Simple Inputs'!$E$28 -> 10 | P7: ='Simple Inputs'!$F$28 -> 4.99 | Q7: =P7/O7 -> 0.499 | T7: Career Compass | U7: 3 | V7: 3 | Z7: Linkedin Grader | AA7: 4600 | AB7: 1400 | AD7: Linkedin Grader | AE7: 5200 | AF7: 4700 | AH7: Linkedin Grader | AI7: 0 | AJ7: 4700 | AL7: Linkedin Grader | AM7: 0 | AN7: 0
A8: Revenue | B8: =$F$26 -> 26258.726 | E8: Annual # | F8: - | G8: =FLOOR(G6*$K$4, 1) -> 120 | J8: Cost (Monthly plan) | K8: - | L8: ='Simple Inputs'!$E$13 -> 16.99 | O8: ='Simple Inputs'!$E$29 -> 25 | P8: ='Simple Inputs'!$F$29 -> 9.99 | Q8: =P8/O8 -> 0.3996 | T8: Linkedin Grader | U8: 3 | V8: 3 | Z8: Career Compass | AA8: 5300 | AB8: 14000 | AD8: Career Compass | AE8: 2500 | AF8: 6100 | AH8: Career Compass | AI8: 0 | AJ8: 0 | AL8: Career Compass | AM8: 0 | AN8: 0
A9: Payment losses | B9: =-$F$27 -> 2182.297 | E9: Annual # (monthly equivalent) | F9: - | G9: =FLOOR(G8/12, 1) -> 10 | J9: Cost (Annual plan) | K9: - | L9: ='Simple Inputs'!$E$14/12 -> 14.165833 | O9: ='Simple Inputs'!$E$30 -> 50 | P9: ='Simple Inputs'!$F$30 -> 17.99 | Q9: =P9/O9 -> 0.3598 | T9: Recruiting Lens | U9: - | V9: 5 | Z9: Recruiting Lens | AA9: - | AB9: 13000 | AD9: Recruiting Lens | AE9: - | AF9: 22000 | AH9: Recruiting Lens | AI9: - | AJ9: 0 | AL9: Recruiting Lens | AM9: - | AN9: 0
A10: Stripe fees | B10: =-$F$28 -> 1692.366 | T10: Interview Prep Coach | U10: - | V10: - | Z10: Interview Prep Coach | AA10: - | AB10: - | AD10: Interview Prep Coach | AE10: - | AF10: - | AH10: Interview Prep Coach (standard) | AI10: - | AJ10: - | AL10: Interview Prep Coach | AM10: - | AN10: -
A11: AI costs | B11: =-$F$29 -> 14941.115 | E11: Max merit use/ month / user | J11: Stripe fees | Z11: TOTAL IINPUT TOKENS | AA11: =SUM(AA6:AA10) -> 15000 | AB11: =SUM(AB6:AB10) -> 48400 | AD11: TOTAL OUTPUT TOKENS | AE11: =SUM(AE6:AE10) -> 12000 | AF11: =SUM(AF6:AF9) -> 57800 | AH11: TOTAL CACHE-WRITE TOKENS | AI11: =SUM(AI6:AI8) -> 0 | AJ11: =SUM(AJ6:AJ9) -> 4700 | AL11: TOTAL CACHE-READ TOKENS | AM11: =SUM(AM6:AM10) -> 0 | AN11: =SUM(AN6:AN10) -> 0
A12: Document processing | B12: =-$F$30 -> 125.952 | E12: Membership | F12: Max merits / month | G12: Max cost | H12: Margin | J12: Fee type | K12: Value
A13: Software & infrastructure | B13: =-$F$31 -> 151.14 | E13: Free | F13: 10 | G13: =(AA30*AM15)+(AA31*AM16)+(AA32*AM17) -> -0.075 | H13: - | J13: Variable fee | K13: ='Simple Inputs'!$E$10 -> 0.029 | O13: Shop Assumptions - % | T13: Shop Assumptions - $ Charged | Z13: Cost per run - Input $ | AD13: Cost per run - Output $ | AH13: Cost per run - Cache Total $ | AL13: Cost per run - TOTAL $
A14: Total monthly costs | B14: =$F$32 -> 19092.87 | E14: Elite | F14: 150 | G14: =(AB$30*AN15)+(AB$31*AN16)+(AB$32*AN17)+(AB$33*AN18) -> -3.8063 | H14: =(L8+G14)/L8 -> 0.77596822 | J14: Fixed fee | K14: ='Simple Inputs'!$E$11 -> 0.3 | O14: Tier | P14: Free | Q14: Elite | R14: Total | T14: Tier | U14: Free | V14: Elite | W14: Total | Z14: Features | AA14: Free | AB14: Elite | AD14: Features | AE14: Free | AF14: Elite | AH14: Features | AI14: Free | AJ14: Elite | AL14: Features | AM14: Free | AN14: Elite
A15: Net profit | B15: =$F$36 -> 7165.8558 | O15: 3 Merits | P15: 0.01 | Q15: 0.0038 | R15: =SUM(P15:Q15) -> 0.0138 | T15: 3 Merits | U15: =(P24*P6) -> 2364.12 | V15: =Q24*$P6 -> 9.0744 | W15: =SUM(U15:V15) -> 2373.1944 | Z15: Resume Analysis | AA15: =AA6*$AF$29*-1 -> -0.0051 | AB15: =AB6*$AF$29*-1 -> -0.02 | AD15: Resume Analysis | AE15: =AE6*$AF$32*-1 -> -0.0215 | AF15: =AF6*$AF$32*-1 -> -0.125 | AH15: Resume Analysis | AI15: =-(AI6*$AF$30+AM6*$AF$31) -> 0 | AJ15: =-(AJ6*$AF$30+AN6*$AF$31) -> 0 | AL15: Resume Analysis | AM15: =AI15+AE15+AA15 -> -0.0266 | AN15: =AJ15+AF15+AB15 -> -0.145
A16: Profit margin | B16: =$F$37 -> 0.27289427 | E16: Stripe & AI Cost | O16: 10 Merits | P16: 0.003 | Q16: 0.0012 | R16: =SUM(P16:Q16) -> 0.0042 | T16: 10 Merits | U16: =P25*P7 -> 1778.436 | V16: =Q25*$P7 -> 7.1856 | W16: =SUM(U16:V16) -> 1785.6216 | Z16: Linkedin Grader | AA16: =AA7*$AF$29*-1 -> -0.0046 | AB16: =AB7*$AF$29*-1 -> -0.0014 | AD16: Linkedin Grader | AE16: =AE7*$AF$32*-1 -> -0.026 | AF16: =AF7*$AF$32*-1 -> -0.0235 | AH16: Linkedin Grader | AI16: =-(AI7*$AF$30+AM7*$AF$31) -> 0 | AJ16: =-(AJ7*$AF$30+AN7*$AF$31) -> -0.005875 | AL16: Linkedin Grader | AM16: =AI16+AE16+AA16 -> -0.0306 | AN16: =AJ16+AF16+AB16 -> -0.030775
A17: Founder take-home | B17: =$F$40 -> 2364.7324 | E17: Transaction type | F17: Transactions/month | G17: Average charge | H17: Gross revenue | I17: Stripe fees | J17: AI cost | K17: Profit | O17: 25 Merits | P17: 0.001 | Q17: 0.0004 | R17: =SUM(P17:Q17) -> 0.0014 | T17: 25 Merits | U17: =P26*P8 -> 1186.812 | V17: =Q26*$P8 -> 4.7952 | W17: =SUM(U17:V17) -> 1191.6072 | Z17: Career Compass | AA17: =AA8*$AF$29*-1 -> -0.0053 | AB17: =AB8*$AF$29*-1 -> -0.014 | AD17: Career Compass | AE17: =AE8*$AF$32*-1 -> -0.0125 | AF17: =AF8*$AF$32*-1 -> -0.0305 | AH17: Career Compass | AI17: =-(AI8*$AF$30+AM8*$AF$31) -> 0 | AJ17: =-(AJ8*$AF$30+AN8*$AF$31) -> 0 | AL17: Career Compass | AM17: =AI17+AE17+AA17 -> -0.0178 | AN17: =AJ17+AF17+AB17 -> -0.0445
E18: Free tier usage | F18: 0 | G18: 0 | H18: 0 | I18: 0 | J18: =F7*G13 -> -8910 | K18: =SUM(H18, I18, J18) -> -8910 | O18: 50 Merits | P18: 0.0004 | Q18: 0.0002 | R18: =SUM(P18:Q18) -> 0.0006 | T18: 50 Merits | U18: =P27*P9 -> 854.8848 | V18: =Q27*$P9 -> 4.3176 | W18: =SUM(U18:V18) -> 859.2024 | Z18: Recruiting Lens | AA18: - | AB18: =AB9*$AF$29*-1 -> -0.013 | AD18: Recruiting Lens | AE18: - | AF18: =AF9*$AF$32*-1 -> -0.11 | AH18: Recruiting Lens | AI18: - | AJ18: =-(AJ9*$AF$30+AN9*$AF$31) -> 0 | AL18: Recruiting Lens | AM18: - | AN18: =AJ18+AF18+AB18 -> -0.123
E19: Monthly Elite subscriptions | F19: =G7 -> 1080 | G19: =L8 -> 16.99 | H19: =G19*F19 -> 18349.2 | I19: =SUM(H19*K13*-1, $K$14*F19*-1) -> -856.1268 | J19: =G14*G7 -> -4110.804 | K19: =SUM(H19, I19, J19) -> 13382.269 | O19: Total | P19: =SUM(P15:P18) -> 0.0144 | Q19: =SUM(Q15:Q18) -> 0.0056 | R19: =SUM(R15:R18) -> 0.02 | T19: Total | U19: =SUM(U15:U18) -> 6184.2528 | V19: =SUM(V15:V18) -> 25.3728 | W19: =SUM(W15:W18) -> 6209.6256 | Z19: Interview Prep Coach | AA19: - | AB19: - | AD19: Interview Prep Coach (standard) | AE19: - | AF19: - | AH19: Interview Prep Coach (standard) | AI19: - | AJ19: - | AL19: Interview Prep Coach (standard) | AM19: - | AN19: -
E20: Annual Elite subscriptions | F20: =G9 -> 10 | G20: ='Simple Inputs'!$E$14 -> 169.99 | H20: =G20*F20 -> 1699.9 | I20: =SUM(H20*K13*-1, $K$14*F20*-1) -> -52.2971 | J20: =G14*G8 -> -456.756 | K20: =SUM(H20, I20, J20) -> 1190.8469 | Z20: TOTAL IINPUT COST | AA20: =SUM(AA15:AA17) -> -0.015 | AB20: =SUM(AB15:AB19) -> -0.0484 | AD20: TOTAL OUTPUT COST | AE20: =SUM(AE15:AE17) -> -0.06 | AF20: =SUM(AF15:AF18) -> -0.289 | AH20: TOTAL CACHE COST | AI20: =SUM(AI15:AI17) -> 0 | AJ20: =SUM(AJ15:AJ18) -> -0.005875 | AL20: TOTAL COST | AM20: =SUM(AM15:AM17) -> -0.075 | AN20: =SUM(AN15:AN18) -> -0.343275
E21: Merit shop purchases | F21: =R28 -> 1717.44 | G21: =W19/R28 -> 3.6156288 | H21: =G21*F21 -> 6209.6256 | I21: =SUM(H21*K13*-1, $K$14*F21*-1) -> -695.31114 | J21: =SUMPRODUCT($P$24:$P$27,$O$6:$O$9)*$AA$37+SUMPRODUCT($Q$24:$Q$27,$O$6:$O$9)*$AB$37 -> -105.27155 | K21: =SUM(H21, I21, J21) -> 5409.0429
E22: TOTAL | F22: =SUM(F19:F21) -> 2807.44 | H22: =SUM(H19:H21) -> 26258.726 | I22: =SUM(I18:I21) -> -1603.735 | J22: =SUM(J18:J21) -> -13582.832 | K22: =SUM(K18:K21) -> 11072.159 | O22: Shop Assumptions - Users | T22: Shop Assumptions - $ Profit | Z22: OCR COST MODEL BY TIER
O23: Tier | P23: Free | Q23: Elite | R23: Total | T23: Tier | U23: Free | V23: Elite | W23: Total | Z23: Tier | AA23: Resume Users | AB23: Resume Uploads / User | AC23: Resume Documents | AD23: Resume OCR Rate | AE23: Resume Pages / Doc | AF23: Resume OCR Pages | AG23: LinkedIn Users | AH23: LinkedIn Uploads / User | AI23: LinkedIn Documents | AJ23: LinkedIn OCR Rate | AK23: LinkedIn Pages / Doc | AL23: LinkedIn OCR Pages | AM23: Blended Cost / Page | AN23: Monthly OCR Cost
E24: Monthly Model | O24: 3 Merits | P24: =P15*$F$7 -> 1188 | Q24: =Q15*(G7+G8) -> 4.56 | R24: =SUM(P24:Q24) -> 1192.56 | T24: 3 Merits | U24: =IF(P24 = 0, 0, (P24*($P6*(1-$P$33)-$P$34-($O6*((-1*$G$13)/$AA$36))))) -> 1909.4605 | V24: =IF(Q24 = 0, 0, (Q24*($P6*(1-$P$33)-$P$34-($O6*((-1*$G$14)/$AB$36))))) -> 7.0961078 | W24: =SUM(U24:V24) -> 1916.5566 | Z24: Free | AA24: =$F$7 -> 118800 | AB24: ='Simple Inputs'!$E$21 -> 1 | AC24: =AA24*AB24 -> 118800 | AD24: ='Simple Inputs'!$E$17 -> 0.1 | AE24: ='Simple Inputs'!$E$18 -> 2 | AF24: =AC24*AD24*AE24 -> 23760 | AG24: =$F$7 -> 118800 | AH24: ='Simple Inputs'!$E$23 -> 0.1 | AI24: =AG24*AH24 -> 11880 | AJ24: ='Simple Inputs'!$E$19 -> 0.1 | AK24: ='Simple Inputs'!$E$20 -> 6 | AL24: =AI24*AJ24*AK24 -> 7128 | AM24: ='Simple Inputs'!$E$38 -> 0.004 | AN24: =(AF24+AL24)*AM24 -> 123.552
E25: Line Item | F25: Monthly Amount | G25: Annualized / KPI | H25: Classification | I25: Input Status | O25: 10 Merits | P25: =P16*F7 -> 356.4 | Q25: =Q16*(G7+G8) -> 1.44 | R25: =SUM(P25:Q25) -> 357.84 | T25: 10 Merits | U25: =IF(P25 = 0, 0, (P25*($P7*(1-$P$33)-$P$34-($O7*((-1*$G$13)/$AA$36))))) -> 1590.2414 | V25: =IF(Q25 = 0, 0, (Q25*($P7*(1-$P$33)-$P$34-($O7*((-1*$G$14)/$AB$36))))) -> 6.1798128 | W25: =SUM(U25:V25) -> 1596.4212 | Z25: Elite | AA25: =SUM($G$7:$G$8) -> 1200 | AB25: ='Simple Inputs'!$E$22 -> 1 | AC25: =AA25*AB25 -> 1200 | AD25: ='Simple Inputs'!$E$17 -> 0.1 | AE25: ='Simple Inputs'!$E$18 -> 2 | AF25: =AC25*AD25*AE25 -> 240 | AG25: =SUM($G$7:$G$8) -> 1200 | AH25: ='Simple Inputs'!$E$24 -> 0.5 | AI25: =AG25*AH25 -> 600 | AJ25: ='Simple Inputs'!$E$19 -> 0.1 | AK25: ='Simple Inputs'!$E$20 -> 6 | AL25: =AI25*AJ25*AK25 -> 360 | AM25: ='Simple Inputs'!$E$39 -> 0.004 | AN25: =(AF25+AL25)*AM25 -> 2.4
E26: Gross revenue | F26: =$H$22 -> 26258.726 | G26: =F26*12 -> 315104.71 | H26: Revenue | I26: Scenario formula | O26: 25 Merits | P26: =P17*$F$7 -> 118.8 | Q26: =Q17*(G7+G8) -> 0.48 | R26: =SUM(P26:Q26) -> 119.28 | T26: 25 Merits | U26: =IF(P26 = 0, 0, (P26*($P8*(1-$P$33)-$P$34-($O8*((-1*$G$13)/$AA$36))))) -> 1092.0045 | V26: =IF(Q26 = 0, 0, (Q26*($P8*(1-$P$33)-$P$34-($O8*((-1*$G$14)/$AB$36))))) -> 4.2076352 | W26: =SUM(U26:V26) -> 1096.2121 | Z26: Total | AA26: =SUM(AA24:AA25) -> 120000 | AB26: - | AC26: =SUM(AC24:AC25) -> 120000 | AD26: - | AE26: - | AF26: =SUM(AF24:AF25) -> 24000 | AG26: =SUM(AG24:AG25) -> 120000 | AH26: - | AI26: =SUM(AI24:AI25) -> 12480 | AJ26: - | AK26: - | AL26: =SUM(AL24:AL25) -> 7488 | AM26: - | AN26: =SUM(AN24:AN25) -> 125.952
E27: Failed payments, refunds, and chargebacks | F27: =SUM($S$41,$S$43,$S$45) -> -2182.297 | G27: =F27*12 -> -26187.564 | H27: Cost | I27: Estimate dependent | O27: 50 Merits | P27: =P18*$F$7 -> 47.52 | Q27: =Q18*(G7+G8) -> 0.24 | R27: =SUM(P27:Q27) -> 47.76 | T27: 50 Merits | U27: =IF(P27 = 0, 0, (P27*($P9*(1-$P$33)-$P$34-($O9*((-1*$G$13)/$AA$36))))) -> 796.03714 | V27: =IF(Q27 = 0, 0, (Q27*($P9*(1-$P$33)-$P$34-($O9*((-1*$G$14)/$AB$36))))) -> 3.8158856 | W27: =SUM(U27:V27) -> 799.85303
E28: Stripe processing, fixed, dispute, and Billing fees | F28: =SUM($S$47:$S$50) -> -1692.366 | G28: =F28*12 -> -20308.392 | H28: Cost | I28: Official rates; mix estimated | O28: Total | P28: =SUM(P24:P27) -> 1710.72 | Q28: =SUM(Q24:Q27) -> 6.72 | R28: =SUM(R24:R27) -> 1717.44 | T28: Total | U28: =SUM(U24:U27) -> 5387.7435 | V28: =SUM(V24:V27) -> 21.299441 | W28: =SUM(W24:W27) -> 5409.0429 | Z28: Assumed usage distribution | AD28: AI Information | AH28: VENDOR COST DETAIL
E29: AI inference including retry/failure overhead | F29: =$J$22*(1+'Simple Inputs'!$E$9) -> -14941.115 | G29: =F29*12 -> -179293.38 | H29: Cost | I29: Estimate dependent | Z29: Features | AA29: Free (10 merits) | AB29: Elite (150 merits) | AD29: Input cost | AE29: $1/1M Input Tokens | AF29: =1/1000000 -> 1e-06 | AH29: Component | AI29: Monthly Cost | AJ29: Calculation
E30: OCR processing | F30: =-$AN$26 -> -125.952 | G30: =F30*12 -> -1511.424 | H30: Cost | I30: Estimate dependent | Z30: Resume Analysis | AA30: 1 | AB30: 13 | AD30: Cache write cost | AE30: $1.25/1M Cache-Write Tokens | AF30: =1.25/1000000 -> 1.25e-06 | AH30: Supabase Pro base | AI30: ='Simple Inputs'!$P$46 -> 25 | AJ30: Central base plan
E31: Platform, domain, and developer tools | F31: =-$AI$37 -> -151.14 | G31: =F31*12 -> -1813.68 | H31: Cost | I31: Source backed; usage estimated | O31: Stripe fees | T31: Shop Prices | Z31: Linkedin Grader | AA31: 1 | AB31: 12 | AD31: Cache read cost | AE31: $0.10/1M Cache-Read Tokens | AF31: =0.1/1000000 -> 1e-07 | AH31: Supabase MAU overage | AI31: =IF('Simple Inputs'!$F$47="Yes",MAX(0,$K$4-'Simple Inputs'!$M$47)*'Simple Inputs'!$N$47,0) -> 65 | AJ31: Scenario MAU above allowance
E32: Total modeled cost | F32: =-SUM(F27:F31) -> 19092.87 | G32: =F32*12 -> 229114.44 | H32: KPI | I32: Calculated | O32: Fee type | P32: Value | T32: Count | U32: Price | Z32: Career Compass | AA32: 1 | AB32: 10 | AD32: Output cost | AE32: $5/1M Output Tokens | AF32: 5e-06 | AH32: Supabase other dimensions | AI32: =SUM('Simple Inputs'!$P$48:$P$55) -> 0 | AJ32: Central reference usage schedule
E33: Total modeled cost per MAU | F33: =IFERROR(F32/$K$4,0) -> 0.15910725 | G33: =F33 -> 0.15910725 | H33: KPI | I33: Calculated | O33: Variable fee | P33: ='Simple Inputs'!$E$10 -> 0.029 | T33: ='Simple Inputs'!$E$27 -> 3 | U33: ='Simple Inputs'!$F$27 -> 1.99 | Z33: Recruiting Lens | AA33: - | AB33: 9 | AD33: Model used for all features | AE33: claude-haiku-4-5-20251001 | AH33: Vercel Pro and usage | AI33: =SUM('Simple Inputs'!$P$56:$P$62) -> 20 | AJ33: Central reference usage schedule
E34: AI plus OCR cost per MAU | F34: =IFERROR(-(F29+F30)/$K$4,0) -> 0.12555889 | G34: =F34 -> 0.12555889 | H34: KPI | I34: Estimate dependent | O34: Fixed fee | P34: ='Simple Inputs'!$E$11 -> 0.3 | T34: ='Simple Inputs'!$E$28 -> 10 | U34: ='Simple Inputs'!$F$28 -> 4.99 | Z34: Interview Prep Coach | AA34: - | AB34: - | AH34: Domain | AI34: ='Simple Inputs'!$P$63 -> 1.14 | AJ34: Date-aware current term / renewal
E35: Vendor cost per MAU | F35: =IFERROR(-F31/$K$4,0) -> 0.0012595 | G35: =F35 -> 0.0012595 | H35: KPI | I35: Calculated | T35: ='Simple Inputs'!$E$29 -> 25 | U35: ='Simple Inputs'!$F$29 -> 9.99 | Z35: TOTAL RUNS | AA35: =SUM(AA30:AA34) -> 3 | AB35: =SUM(AB30:AB34) -> 44 | AH35: Developer tools | AI35: =SUM('Simple Inputs'!$P$64:$P$65) -> 40 | AJ35: Monthly subscriptions
E36: NET OPERATING PROFIT | F36: =SUM(F26:F31) -> 7165.8558 | G36: =F36*12 -> 85990.27 | H36: Profit | I36: Calculated | T36: ='Simple Inputs'!$E$30 -> 50 | U36: ='Simple Inputs'!$F$30 -> 17.99 | Z36: TOTAL MERITS | AA36: =(AA30*U6)+(AA31*U7)+(AA32*U8) -> 9 | AB36: =(AB30*V6)+(AB31*V7)+(AB32*V8)+(AB33*V9) -> 150 | AH36: Other active recurring services | AI36: =SUM('Simple Inputs'!$P$66:$P$67,'Simple Inputs'!$P$71) -> 0 | AJ36: Only explicitly activated rows
E37: Net operating margin | F37: =IFERROR(F36/F26,0) -> 0.27289427 | G37: =F37 -> 0.27289427 | H37: KPI | I37: Calculated | Z37: COST PER MERIT | AA37: =$G$13/AA36 -> -0.0083333333 | AB37: =$G$14/AB36 -> -0.025375333 | AH37: TOTAL VENDOR COST | AI37: =SUM(AI30:AI36) -> 151.14 | AJ37: Sum of vendor components
E38: Founder share before tax | F38: =F36/'Simple Inputs'!$E$16 -> 3582.9279 | G38: =F38*12 -> 42995.135 | H38: Founder | I38: Calculated | O38: PAYMENT LOSS
E39: Founder tax reserve | F39: =-MAX(0,F38)*'Simple Inputs'!$E$15 -> -1218.1955 | G39: =F39*12 -> -14618.346 | H39: Founder | I39: Existing assumption | O39: Line Item | P39: Monthly Subs | Q39: Annual Subs | R39: Merit Shop | S39: Total | T39: Calculation Logic
E40: FOUNDER TAKE-HOME | F40: =SUM(F38:F39) -> 2364.7324 | G40: =F40*12 -> 28376.789 | H40: Founder | I40: Calculated | O40: Gross billed | P40: =$H$19 -> 18349.2 | Q40: =$H$20 -> 1699.9 | R40: =$H$21 -> 6209.6256 | S40: =SUM(P40:R40) -> 26258.726 | T40: Scenario gross billed
...

Sheet Mid Case
A1: MID CASE | H1: OVERVIEW | S1: MERIT SHOP | AG1: AI COSTING
A2: SCENARIO INPUTS
A3: Total monthly users | B3: 120000
A4: Monthly Elite users | B4: 0.034 | E4: MAU tier distributions | F4: Free | G4: Elite | J4: MAU's | K4: =$B$3 -> 120000 | O4: Shop Prices | T4: Cost of features in Merits | Z4: Tokens per run - Input # | AD4: Tokens per run - Output # | AH4: Tokens per run - Cache Write # | AL4: Tokens per run - Cache Read #
A5: Annual Elite users | B5: 0.006 | E5: Monthly % | F5: =1-$B$4-$B$5 -> 0.96 | G5: =$B$4 -> 0.034 | O5: Count | P5: Price | Q5: Price per merit | T5: Features | U5: Free | V5: Elite | Z5: Features | AA5: Free | AB5: Elite | AD5: Features | AE5: Free | AF5: Elite | AH5: Features | AI5: Free | AJ5: Elite | AL5: Features | AM5: Free | AN5: Elite
E6: Annual % | F6: - | G6: =$B$5 -> 0.006 | J6: Monthly cost of plans | O6: ='Simple Inputs'!$E$27 -> 3 | P6: ='Simple Inputs'!$F$27 -> 1.99 | Q6: =P6/O6 -> 0.66333333 | T6: Resume Analysis | U6: 3 | V6: 3 | Z6: Resume Analysis | AA6: 5100 | AB6: 20000 | AD6: Resume Analysis | AE6: 4300 | AF6: 25000 | AH6: Resume Analysis | AI6: 0 | AJ6: 0 | AL6: Resume Analysis | AM6: 0 | AN6: 0
A7: MONTHLY RESULTS | E7: Monthly # | F7: =FLOOR(F5*$K$4, 1) -> 115200 | G7: =FLOOR(G5*$K$4, 1) -> 4080 | J7: Tier | K7: Free | L7: Elite | O7: ='Simple Inputs'!$E$28 -> 10 | P7: ='Simple Inputs'!$F$28 -> 4.99 | Q7: =P7/O7 -> 0.499 | T7: Career Compass | U7: 3 | V7: 3 | Z7: Linkedin Grader | AA7: 4600 | AB7: 1400 | AD7: Linkedin Grader | AE7: 5200 | AF7: 4700 | AH7: Linkedin Grader | AI7: 0 | AJ7: 4700 | AL7: Linkedin Grader | AM7: 0 | AN7: 0
A8: Revenue | B8: =$F$26 -> 88666.114 | E8: Annual # | F8: - | G8: =FLOOR(G6*$K$4, 1) -> 720 | J8: Cost (Monthly plan) | K8: - | L8: ='Simple Inputs'!$E$13 -> 16.99 | O8: ='Simple Inputs'!$E$29 -> 25 | P8: ='Simple Inputs'!$F$29 -> 9.99 | Q8: =P8/O8 -> 0.3996 | T8: Linkedin Grader | U8: 3 | V8: 3 | Z8: Career Compass | AA8: 5300 | AB8: 14000 | AD8: Career Compass | AE8: 2500 | AF8: 6100 | AH8: Career Compass | AI8: 0 | AJ8: 0 | AL8: Career Compass | AM8: 0 | AN8: 0
A9: Payment losses | B9: =-$F$27 -> 7368.819 | E9: Annual # (monthly equivalent) | F9: - | G9: =FLOOR(G8/12, 1) -> 60 | J9: Cost (Annual plan) | K9: - | L9: ='Simple Inputs'!$E$14/12 -> 14.165833 | O9: ='Simple Inputs'!$E$30 -> 50 | P9: ='Simple Inputs'!$F$30 -> 17.99 | Q9: =P9/O9 -> 0.3598 | T9: Recruiting Lens | U9: - | V9: 5 | Z9: Recruiting Lens | AA9: - | AB9: 13000 | AD9: Recruiting Lens | AE9: - | AF9: 22000 | AH9: Recruiting Lens | AI9: - | AJ9: 0 | AL9: Recruiting Lens | AM9: - | AN9: 0
A10: Stripe fees | B10: =-$F$28 -> 4719.0703 | T10: Interview Prep Coach | U10: - | V10: - | Z10: Interview Prep Coach | AA10: - | AB10: - | AD10: Interview Prep Coach | AE10: - | AF10: - | AH10: Interview Prep Coach (standard) | AI10: - | AJ10: - | AL10: Interview Prep Coach | AM10: - | AN10: -
A11: AI costs | B11: =-$F$29 -> 17935.801 | E11: Max merit use/ month / user | J11: Stripe fees | Z11: TOTAL IINPUT TOKENS | AA11: =SUM(AA6:AA10) -> 15000 | AB11: =SUM(AB6:AB10) -> 48400 | AD11: TOTAL OUTPUT TOKENS | AE11: =SUM(AE6:AE10) -> 12000 | AF11: =SUM(AF6:AF9) -> 57800 | AH11: TOTAL CACHE-WRITE TOKENS | AI11: =SUM(AI6:AI8) -> 0 | AJ11: =SUM(AJ6:AJ9) -> 4700 | AL11: TOTAL CACHE-READ TOKENS | AM11: =SUM(AM6:AM10) -> 0 | AN11: =SUM(AN6:AN10) -> 0
A12: Document processing | B12: =-$F$30 -> 129.408 | E12: Membership | F12: Max merits / month | G12: Max cost | H12: Margin | J12: Fee type | K12: Value
A13: Software & infrastructure | B13: =-$F$31 -> 151.14 | E13: Free | F13: 10 | G13: =(AA30*AM15)+(AA31*AM16)+(AA32*AM17) -> -0.045 | H13: - | J13: Variable fee | K13: ='Simple Inputs'!$E$10 -> 0.029 | O13: Shop Assumptions - % | T13: Shop Assumptions - $ Charged | Z13: Cost per run - Input $ | AD13: Cost per run - Output $ | AH13: Cost per run - Cache Total $ | AL13: Cost per run - TOTAL $
A14: Total monthly costs | B14: =$F$32 -> 30304.238 | E14: Elite | F14: 150 | G14: =(AB$30*AN15)+(AB$31*AN16)+(AB$32*AN17)+(AB$33*AN18) -> -2.28378 | H14: =(L8+G14)/L8 -> 0.86558093 | J14: Fixed fee | K14: ='Simple Inputs'!$E$11 -> 0.3 | O14: Tier | P14: Free | Q14: Elite | R14: Total | T14: Tier | U14: Free | V14: Elite | W14: Total | Z14: Features | AA14: Free | AB14: Elite | AD14: Features | AE14: Free | AF14: Elite | AH14: Features | AI14: Free | AJ14: Elite | AL14: Features | AM14: Free | AN14: Elite
A15: Net profit | B15: =$F$36 -> 58361.876 | O15: 3 Merits | P15: 0.015 | Q15: 0.0057 | R15: =SUM(P15:Q15) -> 0.0207 | T15: 3 Merits | U15: =(P24*P6) -> 3438.72 | V15: =Q24*$P6 -> 54.4464 | W15: =SUM(U15:V15) -> 3493.1664 | Z15: Resume Analysis | AA15: =AA6*$AF$29*-1 -> -0.0051 | AB15: =AB6*$AF$29*-1 -> -0.02 | AD15: Resume Analysis | AE15: =AE6*$AF$32*-1 -> -0.0215 | AF15: =AF6*$AF$32*-1 -> -0.125 | AH15: Resume Analysis | AI15: =-(AI6*$AF$30+AM6*$AF$31) -> 0 | AJ15: =-(AJ6*$AF$30+AN6*$AF$31) -> 0 | AL15: Resume Analysis | AM15: =AI15+AE15+AA15 -> -0.0266 | AN15: =AJ15+AF15+AB15 -> -0.145
A16: Profit margin | B16: =$F$37 -> 0.65822075 | E16: Stripe & AI Cost | O16: 10 Merits | P16: 0.0045 | Q16: 0.0018 | R16: =SUM(P16:Q16) -> 0.0063 | T16: 10 Merits | U16: =P25*P7 -> 2586.816 | V16: =Q25*$P7 -> 43.1136 | W16: =SUM(U16:V16) -> 2629.9296 | Z16: Linkedin Grader | AA16: =AA7*$AF$29*-1 -> -0.0046 | AB16: =AB7*$AF$29*-1 -> -0.0014 | AD16: Linkedin Grader | AE16: =AE7*$AF$32*-1 -> -0.026 | AF16: =AF7*$AF$32*-1 -> -0.0235 | AH16: Linkedin Grader | AI16: =-(AI7*$AF$30+AM7*$AF$31) -> 0 | AJ16: =-(AJ7*$AF$30+AN7*$AF$31) -> -0.005875 | AL16: Linkedin Grader | AM16: =AI16+AE16+AA16 -> -0.0306 | AN16: =AJ16+AF16+AB16 -> -0.030775
A17: Founder take-home | B17: =$F$40 -> 19259.419 | E17: Transaction type | F17: Transactions/month | G17: Average charge | H17: Gross revenue | I17: Stripe fees | J17: AI cost | K17: Profit | O17: 25 Merits | P17: 0.0015 | Q17: 0.0006 | R17: =SUM(P17:Q17) -> 0.0021 | T17: 25 Merits | U17: =P26*P8 -> 1726.272 | V17: =Q26*$P8 -> 28.7712 | W17: =SUM(U17:V17) -> 1755.0432 | Z17: Career Compass | AA17: =AA8*$AF$29*-1 -> -0.0053 | AB17: =AB8*$AF$29*-1 -> -0.014 | AD17: Career Compass | AE17: =AE8*$AF$32*-1 -> -0.0125 | AF17: =AF8*$AF$32*-1 -> -0.0305 | AH17: Career Compass | AI17: =-(AI8*$AF$30+AM8*$AF$31) -> 0 | AJ17: =-(AJ8*$AF$30+AN8*$AF$31) -> 0 | AL17: Career Compass | AM17: =AI17+AE17+AA17 -> -0.0178 | AN17: =AJ17+AF17+AB17 -> -0.0445
E18: Free tier usage | F18: 0 | G18: 0 | H18: 0 | I18: 0 | J18: =F7*G13 -> -5184 | K18: =SUM(H18, I18, J18) -> -5184 | O18: 50 Merits | P18: 0.0006 | Q18: 0.0003 | R18: =SUM(P18:Q18) -> 0.0009 | T18: 50 Merits | U18: =P27*P9 -> 1243.4688 | V18: =Q27*$P9 -> 25.9056 | W18: =SUM(U18:V18) -> 1269.3744 | Z18: Recruiting Lens | AA18: - | AB18: =AB9*$AF$29*-1 -> -0.013 | AD18: Recruiting Lens | AE18: - | AF18: =AF9*$AF$32*-1 -> -0.11 | AH18: Recruiting Lens | AI18: - | AJ18: =-(AJ9*$AF$30+AN9*$AF$31) -> 0 | AL18: Recruiting Lens | AM18: - | AN18: =AJ18+AF18+AB18 -> -0.123
E19: Monthly Elite subscriptions | F19: =G7 -> 4080 | G19: =L8 -> 16.99 | H19: =G19*F19 -> 69319.2 | I19: =SUM(H19*K13*-1, $K$14*F19*-1) -> -3234.2568 | J19: =G14*G7 -> -9317.8224 | K19: =SUM(H19, I19, J19) -> 56767.121 | O19: Total | P19: =SUM(P15:P18) -> 0.0216 | Q19: =SUM(Q15:Q18) -> 0.0084 | R19: =SUM(R15:R18) -> 0.03 | T19: Total | U19: =SUM(U15:U18) -> 8995.2768 | V19: =SUM(V15:V18) -> 152.2368 | W19: =SUM(W15:W18) -> 9147.5136 | Z19: Interview Prep Coach | AA19: - | AB19: - | AD19: Interview Prep Coach (standard) | AE19: - | AF19: - | AH19: Interview Prep Coach (standard) | AI19: - | AJ19: - | AL19: Interview Prep Coach (standard) | AM19: - | AN19: -
E20: Annual Elite subscriptions | F20: =G9 -> 60 | G20: ='Simple Inputs'!$E$14 -> 169.99 | H20: =G20*F20 -> 10199.4 | I20: =SUM(H20*K13*-1, $K$14*F20*-1) -> -313.7826 | J20: =G14*G8 -> -1644.3216 | K20: =SUM(H20, I20, J20) -> 8241.2958 | Z20: TOTAL IINPUT COST | AA20: =SUM(AA15:AA17) -> -0.015 | AB20: =SUM(AB15:AB19) -> -0.0484 | AD20: TOTAL OUTPUT COST | AE20: =SUM(AE15:AE17) -> -0.06 | AF20: =SUM(AF15:AF18) -> -0.289 | AH20: TOTAL CACHE COST | AI20: =SUM(AI15:AI17) -> 0 | AJ20: =SUM(AJ15:AJ18) -> -0.005875 | AL20: TOTAL COST | AM20: =SUM(AM15:AM17) -> -0.075 | AN20: =SUM(AN15:AN18) -> -0.343275
E21: Merit shop purchases | F21: =R28 -> 2528.64 | G21: =W19/R28 -> 3.6175626 | H21: =G21*F21 -> 9147.5136 | I21: =SUM(H21*K13*-1, $K$14*F21*-1) -> -1023.8699 | J21: =SUMPRODUCT($P$24:$P$27,$O$6:$O$9)*$AA$37+SUMPRODUCT($Q$24:$Q$27,$O$6:$O$9)*$AB$37 -> -159.12928 | K21: =SUM(H21, I21, J21) -> 7964.5144
E22: TOTAL | F22: =SUM(F19:F21) -> 6668.64 | H22: =SUM(H19:H21) -> 88666.114 | I22: =SUM(I18:I21) -> -4571.9093 | J22: =SUM(J18:J21) -> -16305.273 | K22: =SUM(K18:K21) -> 67788.931 | O22: Shop Assumptions - Users | T22: Shop Assumptions - $ Profit | Z22: OCR COST MODEL BY TIER
O23: Tier | P23: Free | Q23: Elite | R23: Total | T23: Tier | U23: Free | V23: Elite | W23: Total | Z23: Tier | AA23: Resume Users | AB23: Resume Uploads / User | AC23: Resume Documents | AD23: Resume OCR Rate | AE23: Resume Pages / Doc | AF23: Resume OCR Pages | AG23: LinkedIn Users | AH23: LinkedIn Uploads / User | AI23: LinkedIn Documents | AJ23: LinkedIn OCR Rate | AK23: LinkedIn Pages / Doc | AL23: LinkedIn OCR Pages | AM23: Blended Cost / Page | AN23: Monthly OCR Cost
E24: Monthly Model | O24: 3 Merits | P24: =P15*$F$7 -> 1728 | Q24: =Q15*(G7+G8) -> 27.36 | R24: =SUM(P24:Q24) -> 1755.36 | T24: 3 Merits | U24: =IF(P24 = 0, 0, (P24*($P6*(1-$P$33)-$P$34-($O6*((-1*$G$13)/$AA$36))))) -> 2777.3971 | V24: =IF(Q24 = 0, 0, (Q24*($P6*(1-$P$33)-$P$34-($O6*((-1*$G$14)/$AB$36))))) -> 42.576647 | W24: =SUM(U24:V24) -> 2819.9738 | Z24: Free | AA24: =$F$7 -> 115200 | AB24: ='Simple Inputs'!$E$21 -> 1 | AC24: =AA24*AB24 -> 115200 | AD24: ='Simple Inputs'!$E$17 -> 0.1 | AE24: ='Simple Inputs'!$E$18 -> 2 | AF24: =AC24*AD24*AE24 -> 23040 | AG24: =$F$7 -> 115200 | AH24: ='Simple Inputs'!$E$23 -> 0.1 | AI24: =AG24*AH24 -> 11520 | AJ24: ='Simple Inputs'!$E$19 -> 0.1 | AK24: ='Simple Inputs'!$E$20 -> 6 | AL24: =AI24*AJ24*AK24 -> 6912 | AM24: ='Simple Inputs'!$E$38 -> 0.004 | AN24: =(AF24+AL24)*AM24 -> 119.808
E25: Line Item | F25: Monthly Amount | G25: Annualized / KPI | H25: Classification | I25: Input Status | O25: 10 Merits | P25: =P16*F7 -> 518.4 | Q25: =Q16*(G7+G8) -> 8.64 | R25: =SUM(P25:Q25) -> 527.04 | T25: 10 Merits | U25: =IF(P25 = 0, 0, (P25*($P7*(1-$P$33)-$P$34-($O7*((-1*$G$13)/$AA$36))))) -> 2313.0783 | V25: =IF(Q25 = 0, 0, (Q25*($P7*(1-$P$33)-$P$34-($O7*((-1*$G$14)/$AB$36))))) -> 37.078877 | W25: =SUM(U25:V25) -> 2350.1572 | Z25: Elite | AA25: =SUM($G$7:$G$8) -> 4800 | AB25: ='Simple Inputs'!$E$22 -> 1 | AC25: =AA25*AB25 -> 4800 | AD25: ='Simple Inputs'!$E$17 -> 0.1 | AE25: ='Simple Inputs'!$E$18 -> 2 | AF25: =AC25*AD25*AE25 -> 960 | AG25: =SUM($G$7:$G$8) -> 4800 | AH25: ='Simple Inputs'!$E$24 -> 0.5 | AI25: =AG25*AH25 -> 2400 | AJ25: ='Simple Inputs'!$E$19 -> 0.1 | AK25: ='Simple Inputs'!$E$20 -> 6 | AL25: =AI25*AJ25*AK25 -> 1440 | AM25: ='Simple Inputs'!$E$39 -> 0.004 | AN25: =(AF25+AL25)*AM25 -> 9.6
E26: Gross revenue | F26: =$H$22 -> 88666.114 | G26: =F26*12 -> 1063993.4 | H26: Revenue | I26: Scenario formula | O26: 25 Merits | P26: =P17*$F$7 -> 172.8 | Q26: =Q17*(G7+G8) -> 2.88 | R26: =SUM(P26:Q26) -> 175.68 | T26: 25 Merits | U26: =IF(P26 = 0, 0, (P26*($P8*(1-$P$33)-$P$34-($O8*((-1*$G$13)/$AA$36))))) -> 1588.3701 | V26: =IF(Q26 = 0, 0, (Q26*($P8*(1-$P$33)-$P$34-($O8*((-1*$G$14)/$AB$36))))) -> 25.245811 | W26: =SUM(U26:V26) -> 1613.6159 | Z26: Total | AA26: =SUM(AA24:AA25) -> 120000 | AB26: - | AC26: =SUM(AC24:AC25) -> 120000 | AD26: - | AE26: - | AF26: =SUM(AF24:AF25) -> 24000 | AG26: =SUM(AG24:AG25) -> 120000 | AH26: - | AI26: =SUM(AI24:AI25) -> 13920 | AJ26: - | AK26: - | AL26: =SUM(AL24:AL25) -> 8352 | AM26: - | AN26: =SUM(AN24:AN25) -> 129.408
E27: Failed payments, refunds, and chargebacks | F27: =SUM($S$41,$S$43,$S$45) -> -7368.819 | G27: =F27*12 -> -88425.828 | H27: Cost | I27: Estimate dependent | O27: 50 Merits | P27: =P18*$F$7 -> 69.12 | Q27: =Q18*(G7+G8) -> 1.44 | R27: =SUM(P27:Q27) -> 70.56 | T27: 50 Merits | U27: =IF(P27 = 0, 0, (P27*($P9*(1-$P$33)-$P$34-($O9*((-1*$G$13)/$AA$36))))) -> 1157.8722 | V27: =IF(Q27 = 0, 0, (Q27*($P9*(1-$P$33)-$P$34-($O9*((-1*$G$14)/$AB$36))))) -> 22.895314 | W27: =SUM(U27:V27) -> 1180.7675
E28: Stripe processing, fixed, dispute, and Billing fees | F28: =SUM($S$47:$S$50) -> -4719.0703 | G28: =F28*12 -> -56628.844 | H28: Cost | I28: Official rates; mix estimated | O28: Total | P28: =SUM(P24:P27) -> 2488.32 | Q28: =SUM(Q24:Q27) -> 40.32 | R28: =SUM(R24:R27) -> 2528.64 | T28: Total | U28: =SUM(U24:U27) -> 7836.7178 | V28: =SUM(V24:V27) -> 127.79665 | W28: =SUM(W24:W27) -> 7964.5144 | Z28: Assumed usage distribution | AD28: AI Information | AH28: VENDOR COST DETAIL
E29: AI inference including retry/failure overhead | F29: =$J$22*(1+'Simple Inputs'!$E$9) -> -17935.801 | G29: =F29*12 -> -215229.61 | H29: Cost | I29: Estimate dependent | Z29: Features | AA29: Free (10 merits) | AB29: Elite (150 merits) | AD29: Input cost | AE29: $1/1M Input Tokens | AF29: =1/1000000 -> 1e-06 | AH29: Component | AI29: Monthly Cost | AJ29: Calculation
E30: OCR processing | F30: =-$AN$26 -> -129.408 | G30: =F30*12 -> -1552.896 | H30: Cost | I30: Estimate dependent | Z30: Resume Analysis | AA30: 0.6 | AB30: 7.8 | AD30: Cache write cost | AE30: $1.25/1M Cache-Write Tokens | AF30: =1.25/1000000 -> 1.25e-06 | AH30: Supabase Pro base | AI30: ='Simple Inputs'!$P$46 -> 25 | AJ30: Central base plan
E31: Platform, domain, and developer tools | F31: =-$AI$37 -> -151.14 | G31: =F31*12 -> -1813.68 | H31: Cost | I31: Source backed; usage estimated | O31: Stripe fees | T31: Shop Prices | Z31: Linkedin Grader | AA31: 0.6 | AB31: 7.2 | AD31: Cache read cost | AE31: $0.10/1M Cache-Read Tokens | AF31: =0.1/1000000 -> 1e-07 | AH31: Supabase MAU overage | AI31: =IF('Simple Inputs'!$F$47="Yes",MAX(0,$K$4-'Simple Inputs'!$M$47)*'Simple Inputs'!$N$47,0) -> 65 | AJ31: Scenario MAU above allowance
E32: Total modeled cost | F32: =-SUM(F27:F31) -> 30304.238 | G32: =F32*12 -> 363650.86 | H32: KPI | I32: Calculated | O32: Fee type | P32: Value | T32: Count | U32: Price | Z32: Career Compass | AA32: 0.6 | AB32: 6 | AD32: Output cost | AE32: $5/1M Output Tokens | AF32: 5e-06 | AH32: Supabase other dimensions | AI32: =SUM('Simple Inputs'!$P$48:$P$55) -> 0 | AJ32: Central reference usage schedule
E33: Total modeled cost per MAU | F33: =IFERROR(F32/$K$4,0) -> 0.25253532 | G33: =F33 -> 0.25253532 | H33: KPI | I33: Calculated | O33: Variable fee | P33: ='Simple Inputs'!$E$10 -> 0.029 | T33: ='Simple Inputs'!$E$27 -> 3 | U33: ='Simple Inputs'!$F$27 -> 1.99 | Z33: Recruiting Lens | AA33: - | AB33: 5.4 | AD33: Model used for all features | AE33: claude-haiku-4-5-20251001 | AH33: Vercel Pro and usage | AI33: =SUM('Simple Inputs'!$P$56:$P$62) -> 20 | AJ33: Central reference usage schedule
E34: AI plus OCR cost per MAU | F34: =IFERROR(-(F29+F30)/$K$4,0) -> 0.15054341 | G34: =F34 -> 0.15054341 | H34: KPI | I34: Estimate dependent | O34: Fixed fee | P34: ='Simple Inputs'!$E$11 -> 0.3 | T34: ='Simple Inputs'!$E$28 -> 10 | U34: ='Simple Inputs'!$F$28 -> 4.99 | Z34: Interview Prep Coach | AA34: - | AB34: - | AH34: Domain | AI34: ='Simple Inputs'!$P$63 -> 1.14 | AJ34: Date-aware current term / renewal
E35: Vendor cost per MAU | F35: =IFERROR(-F31/$K$4,0) -> 0.0012595 | G35: =F35 -> 0.0012595 | H35: KPI | I35: Calculated | T35: ='Simple Inputs'!$E$29 -> 25 | U35: ='Simple Inputs'!$F$29 -> 9.99 | Z35: TOTAL RUNS | AA35: =SUM(AA30:AA34) -> 1.8 | AB35: =SUM(AB30:AB34) -> 26.4 | AH35: Developer tools | AI35: =SUM('Simple Inputs'!$P$64:$P$65) -> 40 | AJ35: Monthly subscriptions
E36: NET OPERATING PROFIT | F36: =SUM(F26:F31) -> 58361.876 | G36: =F36*12 -> 700342.51 | H36: Profit | I36: Calculated | T36: ='Simple Inputs'!$E$30 -> 50 | U36: ='Simple Inputs'!$F$30 -> 17.99 | Z36: TOTAL MERITS | AA36: =(AA30*U6)+(AA31*U7)+(AA32*U8) -> 5.4 | AB36: =(AB30*V6)+(AB31*V7)+(AB32*V8)+(AB33*V9) -> 90 | AH36: Other active recurring services | AI36: =SUM('Simple Inputs'!$P$66:$P$67,'Simple Inputs'!$P$71) -> 0 | AJ36: Only explicitly activated rows
E37: Net operating margin | F37: =IFERROR(F36/F26,0) -> 0.65822075 | G37: =F37 -> 0.65822075 | H37: KPI | I37: Calculated | Z37: COST PER MERIT | AA37: =$G$13/AA36 -> -0.0083333333 | AB37: =$G$14/AB36 -> -0.025375333 | AH37: TOTAL VENDOR COST | AI37: =SUM(AI30:AI36) -> 151.14 | AJ37: Sum of vendor components
E38: Founder share before tax | F38: =F36/'Simple Inputs'!$E$16 -> 29180.938 | G38: =F38*12 -> 350171.25 | H38: Founder | I38: Calculated | O38: PAYMENT LOSS
E39: Founder tax reserve | F39: =-MAX(0,F38)*'Simple Inputs'!$E$15 -> -9921.5189 | G39: =F39*12 -> -119058.23 | H39: Founder | I39: Existing assumption | O39: Line Item | P39: Monthly Subs | Q39: Annual Subs | R39: Merit Shop | S39: Total | T39: Calculation Logic
E40: FOUNDER TAKE-HOME | F40: =SUM(F38:F39) -> 19259.419 | G40: =F40*12 -> 231113.03 | H40: Founder | I40: Calculated | O40: Gross billed | P40: =$H$19 -> 69319.2 | Q40: =$H$20 -> 10199.4 | R40: =$H$21 -> 9147.5136 | S40: =SUM(P40:R40) -> 88666.114 | T40: Scenario gross billed
...

Sheet Best Case
A1: BEST CASE | H1: OVERVIEW | S1: MERIT SHOP | AG1: AI COSTING
A2: SCENARIO INPUTS
A3: Total monthly users | B3: 120000
A4: Monthly Elite users | B4: 0.068 | E4: MAU tier distributions | F4: Free | G4: Elite | J4: MAU's | K4: =$B$3 -> 120000 | O4: Shop Prices | T4: Cost of features in Merits | Z4: Tokens per run - Input # | AD4: Tokens per run - Output # | AH4: Tokens per run - Cache Write # | AL4: Tokens per run - Cache Read #
A5: Annual Elite users | B5: 0.012 | E5: Monthly % | F5: =1-$B$4-$B$5 -> 0.92 | G5: =$B$4 -> 0.068 | O5: Count | P5: Price | Q5: Price per merit | T5: Features | U5: Free | V5: Elite | Z5: Features | AA5: Free | AB5: Elite | AD5: Features | AE5: Free | AF5: Elite | AH5: Features | AI5: Free | AJ5: Elite | AL5: Features | AM5: Free | AN5: Elite
E6: Annual % | F6: - | G6: =$B$5 -> 0.012 | J6: Monthly cost of plans | O6: ='Simple Inputs'!$E$27 -> 3 | P6: ='Simple Inputs'!$F$27 -> 1.99 | Q6: =P6/O6 -> 0.66333333 | T6: Resume Analysis | U6: 3 | V6: 3 | Z6: Resume Analysis | AA6: 5100 | AB6: 20000 | AD6: Resume Analysis | AE6: 4300 | AF6: 25000 | AH6: Resume Analysis | AI6: 0 | AJ6: 0 | AL6: Resume Analysis | AM6: 0 | AN6: 0
A7: MONTHLY RESULTS | E7: Monthly # | F7: =FLOOR(F5*$K$4, 1) -> 110400 | G7: =FLOOR(G5*$K$4, 1) -> 8160 | J7: Tier | K7: Free | L7: Elite | O7: ='Simple Inputs'!$E$28 -> 10 | P7: ='Simple Inputs'!$F$28 -> 4.99 | Q7: =P7/O7 -> 0.499 | T7: Career Compass | U7: 3 | V7: 3 | Z7: Linkedin Grader | AA7: 4600 | AB7: 1400 | AD7: Linkedin Grader | AE7: 5200 | AF7: 4700 | AH7: Linkedin Grader | AI7: 0 | AJ7: 4700 | AL7: Linkedin Grader | AM7: 0 | AN7: 0
A8: Revenue | B8: =$F$26 -> 173912.11 | E8: Annual # | F8: - | G8: =FLOOR(G6*$K$4, 1) -> 1440 | J8: Cost (Monthly plan) | K8: - | L8: ='Simple Inputs'!$E$13 -> 16.99 | O8: ='Simple Inputs'!$E$29 -> 25 | P8: ='Simple Inputs'!$F$29 -> 9.99 | Q8: =P8/O8 -> 0.3996 | T8: Linkedin Grader | U8: 3 | V8: 3 | Z8: Career Compass | AA8: 5300 | AB8: 14000 | AD8: Career Compass | AE8: 2500 | AF8: 6100 | AH8: Career Compass | AI8: 0 | AJ8: 0 | AL8: Career Compass | AM8: 0 | AN8: 0
A9: Payment losses | B9: =-$F$27 -> 14453.401 | E9: Annual # (monthly equivalent) | F9: - | G9: =FLOOR(G8/12, 1) -> 120 | J9: Cost (Annual plan) | K9: - | L9: ='Simple Inputs'!$E$14/12 -> 14.165833 | O9: ='Simple Inputs'!$E$30 -> 50 | P9: ='Simple Inputs'!$F$30 -> 17.99 | Q9: =P9/O9 -> 0.3598 | T9: Recruiting Lens | U9: - | V9: 5 | Z9: Recruiting Lens | AA9: - | AB9: 13000 | AD9: Recruiting Lens | AE9: - | AF9: 22000 | AH9: Recruiting Lens | AI9: - | AJ9: 0 | AL9: Recruiting Lens | AM9: - | AN9: 0
A10: Stripe fees | B10: =-$F$28 -> 9011.3316 | T10: Interview Prep Coach | U10: - | V10: - | Z10: Interview Prep Coach | AA10: - | AB10: - | AD10: Interview Prep Coach | AE10: - | AF10: - | AH10: Interview Prep Coach (standard) | AI10: - | AJ10: - | AL10: Interview Prep Coach | AM10: - | AN10: -
A11: AI costs | B11: =-$F$29 -> 15085.482 | E11: Max merit use/ month / user | J11: Stripe fees | Z11: TOTAL IINPUT TOKENS | AA11: =SUM(AA6:AA10) -> 15000 | AB11: =SUM(AB6:AB10) -> 48400 | AD11: TOTAL OUTPUT TOKENS | AE11: =SUM(AE6:AE10) -> 12000 | AF11: =SUM(AF6:AF9) -> 57800 | AH11: TOTAL CACHE-WRITE TOKENS | AI11: =SUM(AI6:AI8) -> 0 | AJ11: =SUM(AJ6:AJ9) -> 4700 | AL11: TOTAL CACHE-READ TOKENS | AM11: =SUM(AM6:AM10) -> 0 | AN11: =SUM(AN6:AN10) -> 0
A12: Document processing | B12: =-$F$30 -> 134.016 | E12: Membership | F12: Max merits / month | G12: Max cost | H12: Margin | J12: Fee type | K12: Value
A13: Software & infrastructure | B13: =-$F$31 -> 151.14 | E13: Free | F13: 10 | G13: =(AA30*AM15)+(AA31*AM16)+(AA32*AM17) -> -0.0225 | H13: - | J13: Variable fee | K13: ='Simple Inputs'!$E$10 -> 0.029 | O13: Shop Assumptions - % | T13: Shop Assumptions - $ Charged | Z13: Cost per run - Input $ | AD13: Cost per run - Output $ | AH13: Cost per run - Cache Total $ | AL13: Cost per run - TOTAL $
A14: Total monthly costs | B14: =$F$32 -> 38835.371 | E14: Elite | F14: 150 | G14: =(AB$30*AN15)+(AB$31*AN16)+(AB$32*AN17)+(AB$33*AN18) -> -1.14189 | H14: =(L8+G14)/L8 -> 0.93279046 | J14: Fixed fee | K14: ='Simple Inputs'!$E$11 -> 0.3 | O14: Tier | P14: Free | Q14: Elite | R14: Total | T14: Tier | U14: Free | V14: Elite | W14: Total | Z14: Features | AA14: Free | AB14: Elite | AD14: Features | AE14: Free | AF14: Elite | AH14: Features | AI14: Free | AJ14: Elite | AL14: Features | AM14: Free | AN14: Elite
A15: Net profit | B15: =$F$36 -> 135076.74 | O15: 3 Merits | P15: 0.025 | Q15: 0.0095 | R15: =SUM(P15:Q15) -> 0.0345 | T15: 3 Merits | U15: =(P24*P6) -> 5492.4 | V15: =Q24*$P6 -> 181.488 | W15: =SUM(U15:V15) -> 5673.888 | Z15: Resume Analysis | AA15: =AA6*$AF$29*-1 -> -0.0051 | AB15: =AB6*$AF$29*-1 -> -0.02 | AD15: Resume Analysis | AE15: =AE6*$AF$32*-1 -> -0.0215 | AF15: =AF6*$AF$32*-1 -> -0.125 | AH15: Resume Analysis | AI15: =-(AI6*$AF$30+AM6*$AF$31) -> 0 | AJ15: =-(AJ6*$AF$30+AN6*$AF$31) -> 0 | AL15: Resume Analysis | AM15: =AI15+AE15+AA15 -> -0.0266 | AN15: =AJ15+AF15+AB15 -> -0.145
A16: Profit margin | B16: =$F$37 -> 0.77669542 | E16: Stripe & AI Cost | O16: 10 Merits | P16: 0.0075 | Q16: 0.003 | R16: =SUM(P16:Q16) -> 0.0105 | T16: 10 Merits | U16: =P25*P7 -> 4131.72 | V16: =Q25*$P7 -> 143.712 | W16: =SUM(U16:V16) -> 4275.432 | Z16: Linkedin Grader | AA16: =AA7*$AF$29*-1 -> -0.0046 | AB16: =AB7*$AF$29*-1 -> -0.0014 | AD16: Linkedin Grader | AE16: =AE7*$AF$32*-1 -> -0.026 | AF16: =AF7*$AF$32*-1 -> -0.0235 | AH16: Linkedin Grader | AI16: =-(AI7*$AF$30+AM7*$AF$31) -> 0 | AJ16: =-(AJ7*$AF$30+AN7*$AF$31) -> -0.005875 | AL16: Linkedin Grader | AM16: =AI16+AE16+AA16 -> -0.0306 | AN16: =AJ16+AF16+AB16 -> -0.030775
A17: Founder take-home | B17: =$F$40 -> 44575.325 | E17: Transaction type | F17: Transactions/month | G17: Average charge | H17: Gross revenue | I17: Stripe fees | J17: AI cost | K17: Profit | O17: 25 Merits | P17: 0.0025 | Q17: 0.001 | R17: =SUM(P17:Q17) -> 0.0035 | T17: 25 Merits | U17: =P26*P8 -> 2757.24 | V17: =Q26*$P8 -> 95.904 | W17: =SUM(U17:V17) -> 2853.144 | Z17: Career Compass | AA17: =AA8*$AF$29*-1 -> -0.0053 | AB17: =AB8*$AF$29*-1 -> -0.014 | AD17: Career Compass | AE17: =AE8*$AF$32*-1 -> -0.0125 | AF17: =AF8*$AF$32*-1 -> -0.0305 | AH17: Career Compass | AI17: =-(AI8*$AF$30+AM8*$AF$31) -> 0 | AJ17: =-(AJ8*$AF$30+AN8*$AF$31) -> 0 | AL17: Career Compass | AM17: =AI17+AE17+AA17 -> -0.0178 | AN17: =AJ17+AF17+AB17 -> -0.0445
E18: Free tier usage | F18: 0 | G18: 0 | H18: 0 | I18: 0 | J18: =F7*G13 -> -2484 | K18: =SUM(H18, I18, J18) -> -2484 | O18: 50 Merits | P18: 0.001 | Q18: 0.0005 | R18: =SUM(P18:Q18) -> 0.0015 | T18: 50 Merits | U18: =P27*P9 -> 1986.096 | V18: =Q27*$P9 -> 86.352 | W18: =SUM(U18:V18) -> 2072.448 | Z18: Recruiting Lens | AA18: - | AB18: =AB9*$AF$29*-1 -> -0.013 | AD18: Recruiting Lens | AE18: - | AF18: =AF9*$AF$32*-1 -> -0.11 | AH18: Recruiting Lens | AI18: - | AJ18: =-(AJ9*$AF$30+AN9*$AF$31) -> 0 | AL18: Recruiting Lens | AM18: - | AN18: =AJ18+AF18+AB18 -> -0.123
E19: Monthly Elite subscriptions | F19: =G7 -> 8160 | G19: =L8 -> 16.99 | H19: =G19*F19 -> 138638.4 | I19: =SUM(H19*K13*-1, $K$14*F19*-1) -> -6468.5136 | J19: =G14*G7 -> -9317.8224 | K19: =SUM(H19, I19, J19) -> 122852.06 | O19: Total | P19: =SUM(P15:P18) -> 0.036 | Q19: =SUM(Q15:Q18) -> 0.014 | R19: =SUM(R15:R18) -> 0.05 | T19: Total | U19: =SUM(U15:U18) -> 14367.456 | V19: =SUM(V15:V18) -> 507.456 | W19: =SUM(W15:W18) -> 14874.912 | Z19: Interview Prep Coach | AA19: - | AB19: - | AD19: Interview Prep Coach (standard) | AE19: - | AF19: - | AH19: Interview Prep Coach (standard) | AI19: - | AJ19: - | AL19: Interview Prep Coach (standard) | AM19: - | AN19: -
E20: Annual Elite subscriptions | F20: =G9 -> 120 | G20: ='Simple Inputs'!$E$14 -> 169.99 | H20: =G20*F20 -> 20398.8 | I20: =SUM(H20*K13*-1, $K$14*F20*-1) -> -627.5652 | J20: =G14*G8 -> -1644.3216 | K20: =SUM(H20, I20, J20) -> 18126.913 | Z20: TOTAL IINPUT COST | AA20: =SUM(AA15:AA17) -> -0.015 | AB20: =SUM(AB15:AB19) -> -0.0484 | AD20: TOTAL OUTPUT COST | AE20: =SUM(AE15:AE17) -> -0.06 | AF20: =SUM(AF15:AF18) -> -0.289 | AH20: TOTAL CACHE COST | AI20: =SUM(AI15:AI17) -> 0 | AJ20: =SUM(AJ15:AJ18) -> -0.005875 | AL20: TOTAL COST | AM20: =SUM(AM15:AM17) -> -0.075 | AN20: =SUM(AN15:AN18) -> -0.343275
E21: Merit shop purchases | F21: =R28 -> 4108.8 | G21: =W19/R28 -> 3.620257 | H21: =G21*F21 -> 14874.912 | I21: =SUM(H21*K13*-1, $K$14*F21*-1) -> -1664.0124 | J21: =SUMPRODUCT($P$24:$P$27,$O$6:$O$9)*$AA$37+SUMPRODUCT($Q$24:$Q$27,$O$6:$O$9)*$AB$37 -> -267.93095 | K21: =SUM(H21, I21, J21) -> 12942.969
E22: TOTAL | F22: =SUM(F19:F21) -> 12388.8 | H22: =SUM(H19:H21) -> 173912.11 | I22: =SUM(I18:I21) -> -8760.0912 | J22: =SUM(J18:J21) -> -13714.075 | K22: =SUM(K18:K21) -> 151437.95 | O22: Shop Assumptions - Users | T22: Shop Assumptions - $ Profit | Z22: OCR COST MODEL BY TIER
O23: Tier | P23: Free | Q23: Elite | R23: Total | T23: Tier | U23: Free | V23: Elite | W23: Total | Z23: Tier | AA23: Resume Users | AB23: Resume Uploads / User | AC23: Resume Documents | AD23: Resume OCR Rate | AE23: Resume Pages / Doc | AF23: Resume OCR Pages | AG23: LinkedIn Users | AH23: LinkedIn Uploads / User | AI23: LinkedIn Documents | AJ23: LinkedIn OCR Rate | AK23: LinkedIn Pages / Doc | AL23: LinkedIn OCR Pages | AM23: Blended Cost / Page | AN23: Monthly OCR Cost
E24: Monthly Model | O24: 3 Merits | P24: =P15*$F$7 -> 2760 | Q24: =Q15*(G7+G8) -> 91.2 | R24: =SUM(P24:Q24) -> 2851.2 | T24: 3 Merits | U24: =IF(P24 = 0, 0, (P24*($P6*(1-$P$33)-$P$34-($O6*((-1*$G$13)/$AA$36))))) -> 4436.1204 | V24: =IF(Q24 = 0, 0, (Q24*($P6*(1-$P$33)-$P$34-($O6*((-1*$G$14)/$AB$36))))) -> 141.92216 | W24: =SUM(U24:V24) -> 4578.0426 | Z24: Free | AA24: =$F$7 -> 110400 | AB24: ='Simple Inputs'!$E$21 -> 1 | AC24: =AA24*AB24 -> 110400 | AD24: ='Simple Inputs'!$E$17 -> 0.1 | AE24: ='Simple Inputs'!$E$18 -> 2 | AF24: =AC24*AD24*AE24 -> 22080 | AG24: =$F$7 -> 110400 | AH24: ='Simple Inputs'!$E$23 -> 0.1 | AI24: =AG24*AH24 -> 11040 | AJ24: ='Simple Inputs'!$E$19 -> 0.1 | AK24: ='Simple Inputs'!$E$20 -> 6 | AL24: =AI24*AJ24*AK24 -> 6624 | AM24: ='Simple Inputs'!$E$38 -> 0.004 | AN24: =(AF24+AL24)*AM24 -> 114.816
E25: Line Item | F25: Monthly Amount | G25: Annualized / KPI | H25: Classification | I25: Input Status | O25: 10 Merits | P25: =P16*F7 -> 828 | Q25: =Q16*(G7+G8) -> 28.8 | R25: =SUM(P25:Q25) -> 856.8 | T25: 10 Merits | U25: =IF(P25 = 0, 0, (P25*($P7*(1-$P$33)-$P$34-($O7*((-1*$G$13)/$AA$36))))) -> 3694.5001 | V25: =IF(Q25 = 0, 0, (Q25*($P7*(1-$P$33)-$P$34-($O7*((-1*$G$14)/$AB$36))))) -> 123.59626 | W25: =SUM(U25:V25) -> 3818.0964 | Z25: Elite | AA25: =SUM($G$7:$G$8) -> 9600 | AB25: ='Simple Inputs'!$E$22 -> 1 | AC25: =AA25*AB25 -> 9600 | AD25: ='Simple Inputs'!$E$17 -> 0.1 | AE25: ='Simple Inputs'!$E$18 -> 2 | AF25: =AC25*AD25*AE25 -> 1920 | AG25: =SUM($G$7:$G$8) -> 9600 | AH25: ='Simple Inputs'!$E$24 -> 0.5 | AI25: =AG25*AH25 -> 4800 | AJ25: ='Simple Inputs'!$E$19 -> 0.1 | AK25: ='Simple Inputs'!$E$20 -> 6 | AL25: =AI25*AJ25*AK25 -> 2880 | AM25: ='Simple Inputs'!$E$39 -> 0.004 | AN25: =(AF25+AL25)*AM25 -> 19.2
E26: Gross revenue | F26: =$H$22 -> 173912.11 | G26: =F26*12 -> 2086945.3 | H26: Revenue | I26: Scenario formula | O26: 25 Merits | P26: =P17*$F$7 -> 276 | Q26: =Q17*(G7+G8) -> 9.6 | R26: =SUM(P26:Q26) -> 285.6 | T26: 25 Merits | U26: =IF(P26 = 0, 0, (P26*($P8*(1-$P$33)-$P$34-($O8*((-1*$G$13)/$AA$36))))) -> 2536.98 | V26: =IF(Q26 = 0, 0, (Q26*($P8*(1-$P$33)-$P$34-($O8*((-1*$G$14)/$AB$36))))) -> 84.152704 | W26: =SUM(U26:V26) -> 2621.1327 | Z26: Total | AA26: =SUM(AA24:AA25) -> 120000 | AB26: - | AC26: =SUM(AC24:AC25) -> 120000 | AD26: - | AE26: - | AF26: =SUM(AF24:AF25) -> 24000 | AG26: =SUM(AG24:AG25) -> 120000 | AH26: - | AI26: =SUM(AI24:AI25) -> 15840 | AJ26: - | AK26: - | AL26: =SUM(AL24:AL25) -> 9504 | AM26: - | AN26: =SUM(AN24:AN25) -> 134.016
E27: Failed payments, refunds, and chargebacks | F27: =SUM($S$41,$S$43,$S$45) -> -14453.401 | G27: =F27*12 -> -173440.81 | H27: Cost | I27: Estimate dependent | O27: 50 Merits | P27: =P18*$F$7 -> 110.4 | Q27: =Q18*(G7+G8) -> 4.8 | R27: =SUM(P27:Q27) -> 115.2 | T27: 50 Merits | U27: =IF(P27 = 0, 0, (P27*($P9*(1-$P$33)-$P$34-($O9*((-1*$G$13)/$AA$36))))) -> 1849.3792 | V27: =IF(Q27 = 0, 0, (Q27*($P9*(1-$P$33)-$P$34-($O9*((-1*$G$14)/$AB$36))))) -> 76.317712 | W27: =SUM(U27:V27) -> 1925.6969
E28: Stripe processing, fixed, dispute, and Billing fees | F28: =SUM($S$47:$S$50) -> -9011.3316 | G28: =F28*12 -> -108135.98 | H28: Cost | I28: Official rates; mix estimated | O28: Total | P28: =SUM(P24:P27) -> 3974.4 | Q28: =SUM(Q24:Q27) -> 134.4 | R28: =SUM(R24:R27) -> 4108.8 | T28: Total | U28: =SUM(U24:U27) -> 12516.98 | V28: =SUM(V24:V27) -> 425.98883 | W28: =SUM(W24:W27) -> 12942.969 | Z28: Assumed usage distribution | AD28: AI Information | AH28: VENDOR COST DETAIL
E29: AI inference including retry/failure overhead | F29: =$J$22*(1+'Simple Inputs'!$E$9) -> -15085.482 | G29: =F29*12 -> -181025.79 | H29: Cost | I29: Estimate dependent | Z29: Features | AA29: Free (10 merits) | AB29: Elite (150 merits) | AD29: Input cost | AE29: $1/1M Input Tokens | AF29: =1/1000000 -> 1e-06 | AH29: Component | AI29: Monthly Cost | AJ29: Calculation
E30: OCR processing | F30: =-$AN$26 -> -134.016 | G30: =F30*12 -> -1608.192 | H30: Cost | I30: Estimate dependent | Z30: Resume Analysis | AA30: 0.3 | AB30: 3.9 | AD30: Cache write cost | AE30: $1.25/1M Cache-Write Tokens | AF30: =1.25/1000000 -> 1.25e-06 | AH30: Supabase Pro base | AI30: ='Simple Inputs'!$P$46 -> 25 | AJ30: Central base plan
E31: Platform, domain, and developer tools | F31: =-$AI$37 -> -151.14 | G31: =F31*12 -> -1813.68 | H31: Cost | I31: Source backed; usage estimated | O31: Stripe fees | T31: Shop Prices | Z31: Linkedin Grader | AA31: 0.3 | AB31: 3.6 | AD31: Cache read cost | AE31: $0.10/1M Cache-Read Tokens | AF31: =0.1/1000000 -> 1e-07 | AH31: Supabase MAU overage | AI31: =IF('Simple Inputs'!$F$47="Yes",MAX(0,$K$4-'Simple Inputs'!$M$47)*'Simple Inputs'!$N$47,0) -> 65 | AJ31: Scenario MAU above allowance
E32: Total modeled cost | F32: =-SUM(F27:F31) -> 38835.371 | G32: =F32*12 -> 466024.45 | H32: KPI | I32: Calculated | O32: Fee type | P32: Value | T32: Count | U32: Price | Z32: Career Compass | AA32: 0.3 | AB32: 3 | AD32: Output cost | AE32: $5/1M Output Tokens | AF32: 5e-06 | AH32: Supabase other dimensions | AI32: =SUM('Simple Inputs'!$P$48:$P$55) -> 0 | AJ32: Central reference usage schedule
E33: Total modeled cost per MAU | F33: =IFERROR(F32/$K$4,0) -> 0.32362809 | G33: =F33 -> 0.32362809 | H33: KPI | I33: Calculated | O33: Variable fee | P33: ='Simple Inputs'!$E$10 -> 0.029 | T33: ='Simple Inputs'!$E$27 -> 3 | U33: ='Simple Inputs'!$F$27 -> 1.99 | Z33: Recruiting Lens | AA33: - | AB33: 2.7 | AD33: Model used for all features | AE33: claude-haiku-4-5-20251001 | AH33: Vercel Pro and usage | AI33: =SUM('Simple Inputs'!$P$56:$P$62) -> 20 | AJ33: Central reference usage schedule
E34: AI plus OCR cost per MAU | F34: =IFERROR(-(F29+F30)/$K$4,0) -> 0.12682915 | G34: =F34 -> 0.12682915 | H34: KPI | I34: Estimate dependent | O34: Fixed fee | P34: ='Simple Inputs'!$E$11 -> 0.3 | T34: ='Simple Inputs'!$E$28 -> 10 | U34: ='Simple Inputs'!$F$28 -> 4.99 | Z34: Interview Prep Coach | AA34: - | AB34: - | AH34: Domain | AI34: ='Simple Inputs'!$P$63 -> 1.14 | AJ34: Date-aware current term / renewal
E35: Vendor cost per MAU | F35: =IFERROR(-F31/$K$4,0) -> 0.0012595 | G35: =F35 -> 0.0012595 | H35: KPI | I35: Calculated | T35: ='Simple Inputs'!$E$29 -> 25 | U35: ='Simple Inputs'!$F$29 -> 9.99 | Z35: TOTAL RUNS | AA35: =SUM(AA30:AA34) -> 0.9 | AB35: =SUM(AB30:AB34) -> 13.2 | AH35: Developer tools | AI35: =SUM('Simple Inputs'!$P$64:$P$65) -> 40 | AJ35: Monthly subscriptions
E36: NET OPERATING PROFIT | F36: =SUM(F26:F31) -> 135076.74 | G36: =F36*12 -> 1620920.9 | H36: Profit | I36: Calculated | T36: ='Simple Inputs'!$E$30 -> 50 | U36: ='Simple Inputs'!$F$30 -> 17.99 | Z36: TOTAL MERITS | AA36: =(AA30*U6)+(AA31*U7)+(AA32*U8) -> 2.7 | AB36: =(AB30*V6)+(AB31*V7)+(AB32*V8)+(AB33*V9) -> 45 | AH36: Other active recurring services | AI36: =SUM('Simple Inputs'!$P$66:$P$67,'Simple Inputs'!$P$71) -> 0 | AJ36: Only explicitly activated rows
E37: Net operating margin | F37: =IFERROR(F36/F26,0) -> 0.77669542 | G37: =F37 -> 0.77669542 | H37: KPI | I37: Calculated | Z37: COST PER MERIT | AA37: =$G$13/AA36 -> -0.0083333333 | AB37: =$G$14/AB36 -> -0.025375333 | AH37: TOTAL VENDOR COST | AI37: =SUM(AI30:AI36) -> 151.14 | AJ37: Sum of vendor components
E38: Founder share before tax | F38: =F36/'Simple Inputs'!$E$16 -> 67538.371 | G38: =F38*12 -> 810460.45 | H38: Founder | I38: Calculated | O38: PAYMENT LOSS
E39: Founder tax reserve | F39: =-MAX(0,F38)*'Simple Inputs'!$E$15 -> -22963.046 | G39: =F39*12 -> -275556.55 | H39: Founder | I39: Existing assumption | O39: Line Item | P39: Monthly Subs | Q39: Annual Subs | R39: Merit Shop | S39: Total | T39: Calculation Logic
E40: FOUNDER TAKE-HOME | F40: =SUM(F38:F39) -> 44575.325 | G40: =F40*12 -> 534903.89 | H40: Founder | I40: Calculated | O40: Gross billed | P40: =$H$19 -> 138638.4 | Q40: =$H$20 -> 20398.8 | R40: =$H$21 -> 14874.912 | S40: =SUM(P40:R40) -> 173912.11 | T40: Scenario gross billed
...

Sheet Simple Inputs
A1: SIMPLE INPUTS | D1: STRIVO COSTING — SOURCES & INPUTS
A2: Defaults are filled in. Change only blue cells if needed. | D2: Model As-of Date | E2: =DATE(2026,8,1) -> 46235 | F2: Version | G2: Phase 04.1 | H2: Currency | I2: USD | J2: Last Verified | K2: =DATE(2026,8,1) -> 46235
A3: PRICING
A4: Monthly Elite price | B4: 16.99 | D4: GLOBAL OPERATING ASSUMPTIONS
A5: Annual Elite price | B5: 169.99 | D5: Input | E5: Value | F5: Unit | G5: Status | H5: Source ID | I5: Notes
D6: Failed Payment Rate | E6: =$B$8 -> 0.05 | F6: percent | G6: Estimate — production data required | H6: EST-01 | I6: Replace with unrecovered Stripe payment data.
A7: SAFETY ASSUMPTIONS | D7: Refund Rate | E7: =$B$9 -> 0.03 | F7: percent | G7: Estimate — production data required | H7: EST-01 | I7: Replace with refunds divided by collected volume.
A8: Failed payments | B8: 0.05 | D8: Chargeback Rate | E8: =$B$10 -> 0.005 | F8: percent | G8: Estimate — production data required | H8: EST-01 | I8: Replace with disputed volume divided by post-refund volume.
A9: Refunds | B9: 0.03 | D9: AI Retry and Failure Overhead | E9: =$B$11 -> 0.1 | F9: percent | G9: Estimate — production data required | H9: EST-01 | I9: Replace with telemetry cost consumed by retries and failed generations.
A10: Chargebacks | B10: 0.005 | D10: Stripe Variable Fee | E10: 0.029 | F10: percent | G10: Official | H10: STR-01 | I10: US domestic online card rate.
A11: AI cost buffer | B11: 0.1 | D11: Stripe Fixed Fee | E11: 0.3 | F11: USD/transaction | G11: Official | H11: STR-01 | I11: Per successful domestic card charge.
D12: Stripe Dispute Fee | E12: 15 | F12: USD/dispute | G12: Official | H12: STR-04 | I12: Standard US received-dispute fee.
A13: FOUNDER | D13: Monthly Elite Price | E13: =$B$4 -> 16.99 | F13: USD/month | G13: Existing model | H13: MODEL-01 | I13: Preserved current workbook price.
A14: Estimated tax rate | B14: 0.34 | D14: Annual Elite Price | E14: =$B$5 -> 169.99 | F14: USD/year | G14: Existing model | H14: MODEL-01 | I14: Annual transaction economics are calculated annually then divided by 12.
A15: Founder count | B15: 2 | D15: Founder Tax Rate | E15: =$B$14 -> 0.34 | F15: percent | G15: Existing model | H15: MODEL-01 | I15: Preserved current workbook tax assumption.
D16: Founder Count | E16: =$B$15 -> 2 | F16: founders | G16: Existing model | H16: MODEL-01 | I16: Preserved two-founder allocation.
A17: You can safely leave these defaults alone. | D17: Resume OCR Incidence | E17: 0.1 | F17: percent | G17: Estimate — production data required | H17: OCR-EST | I17: Non-zero starting estimate.
D18: Average Resume OCR Pages | E18: 2 | F18: pages/document | G18: Estimate — production data required | H18: OCR-EST | I18: Matches the current two-page resume boundary.
D19: LinkedIn OCR Incidence | E19: 0.1 | F19: percent | G19: Estimate — production data required | H19: OCR-EST | I19: Non-zero starting estimate.
D20: Average LinkedIn OCR Pages | E20: 6 | F20: pages/document | G20: Estimate — production data required | H20: OCR-EST | I20: Within the larger LinkedIn document allowance.
D21: Free Resume Uploads per User | E21: 1 | F21: uploads/month | G21: Estimate — production data required | H21: USE-EST | I21: Replace with feature usage by tier.
D22: Elite Resume Uploads per User | E22: 1 | F22: uploads/month | G22: Estimate — production data required | H22: USE-EST | I22: Replace with feature usage by tier.
D23: Free LinkedIn Uploads per User | E23: 0.1 | F23: uploads/month | G23: Estimate — production data required | H23: USE-EST | I23: Replace with feature usage by tier.
D24: Elite LinkedIn Uploads per User | E24: 0.5 | F24: uploads/month | G24: Estimate — production data required | H24: USE-EST | I24: Replace with feature usage by tier.
D25: MERIT SHOP PRICES
D26: Pack | E26: Merits | F26: Price | G26: Source ID | H26: Status | I26: Notes
D27: 3 Merits | E27: 3 | F27: 1.99 | G27: MODEL-02 | H27: Existing model | I27: Preserved current Merit pack.
D28: 10 Merits | E28: 10 | F28: 4.99 | G28: MODEL-02 | H28: Existing model | I28: Preserved current Merit pack.
D29: 25 Merits | E29: 25 | F29: 9.99 | G29: MODEL-02 | H29: Existing model | I29: Preserved current Merit pack.
D30: 50 Merits | E30: 50 | F30: 17.99 | G30: MODEL-02 | H30: Existing model | I30: Preserved current Merit pack.
D33: OCR PROVIDER BLEND
D34: Provider | E34: Status | F34: Free Share | G34: Elite Share | H34: Cost/Page | I34: Source ID | J34: Notes
D35: Mistral OCR 4 | E35: Official default estimate | F35: 1 | G35: 1 | H35: 0.004 | I35: OCR-01 | J35: Primary modeled OCR provider; replace mix with production routing.
D36: Amazon Textract Detect Text | E36: Not configured | F36: 0 | G36: 0 | H36: 0.0015 | I36: OCR-02 | J36: Visible fallback with zero share until configuration and billing are confirmed.
D37: Claude OCR | E37: Tier-gated; zero modeled share | F37: 0 | G37: 0 | H37: 0.02 | I37: ANT-01 | J37: Allowed only for Elite; replace page estimate with measured telemetry before assigning share.
D38: Free OCR Cost/Page | E38: =SUMPRODUCT(F35:F37,H35:H37) -> 0.004
D39: Elite OCR Cost/Page | E39: =SUMPRODUCT(G35:G37,H35:H37) -> 0.004
D40: Free Provider Weight Check | E40: =IF(ABS(SUM(F35:F37)-1)<0.000001,"OK","ERROR: Free OCR weights") -> OK
D41: Elite Provider Weight Check | E41: =IF(ABS(SUM(G35:G37)-1)<0.000001,"OK","ERROR: Elite OCR weights") -> OK
D43: VENDOR AND PLATFORM COST INPUTS
...
